[2023-09-10T11:40:19.464+0000] {taskinstance.py:1159} INFO - Dependencies all met for dep_context=non-requeueable deps ti=<TaskInstance: file_sensor_dag.trigger_main_dag manual__2023-09-10T11:40:16.298847+00:00 [queued]>
[2023-09-10T11:40:19.476+0000] {taskinstance.py:1159} INFO - Dependencies all met for dep_context=requeueable deps ti=<TaskInstance: file_sensor_dag.trigger_main_dag manual__2023-09-10T11:40:16.298847+00:00 [queued]>
[2023-09-10T11:40:19.477+0000] {taskinstance.py:1361} INFO - Starting attempt 1 of 2
[2023-09-10T11:40:19.489+0000] {taskinstance.py:1382} INFO - Executing <Task(TriggerDagRunOperator): trigger_main_dag> on 2023-09-10 11:40:16.298847+00:00
[2023-09-10T11:40:19.494+0000] {standard_task_runner.py:57} INFO - Started process 924 to run task
[2023-09-10T11:40:19.497+0000] {standard_task_runner.py:84} INFO - Running: ['***', 'tasks', 'run', 'file_sensor_dag', 'trigger_main_dag', 'manual__2023-09-10T11:40:16.298847+00:00', '--job-id', '56', '--raw', '--subdir', 'DAGS_FOLDER/new_file_sensor_dag.py', '--cfg-path', '/tmp/tmph3zz94hh']
[2023-09-10T11:40:19.499+0000] {standard_task_runner.py:85} INFO - Job 56: Subtask trigger_main_dag
[2023-09-10T11:40:19.543+0000] {task_command.py:415} INFO - Running <TaskInstance: file_sensor_dag.trigger_main_dag manual__2023-09-10T11:40:16.298847+00:00 [running]> on host 207c7509dcbb
[2023-09-10T11:40:19.612+0000] {taskinstance.py:1660} INFO - Exporting env vars: AIRFLOW_CTX_DAG_OWNER='you' AIRFLOW_CTX_DAG_ID='file_sensor_dag' AIRFLOW_CTX_TASK_ID='trigger_main_dag' AIRFLOW_CTX_EXECUTION_DATE='2023-09-10T11:40:16.298847+00:00' AIRFLOW_CTX_TRY_NUMBER='1' AIRFLOW_CTX_DAG_RUN_ID='manual__2023-09-10T11:40:16.298847+00:00'
[2023-09-10T11:40:19.627+0000] {taskinstance.py:1943} ERROR - Task failed with exception
Traceback (most recent call last):
  File "/home/airflow/.local/lib/python3.8/site-packages/airflow/operators/trigger_dagrun.py", line 163, in execute
    dag_run = trigger_dag(
  File "/home/airflow/.local/lib/python3.8/site-packages/airflow/api/common/trigger_dag.py", line 119, in trigger_dag
    raise DagNotFound(f"Dag id {dag_id} not found in DagModel")
airflow.exceptions.DagNotFound: Dag id ingest_xl_data_dag not found in DagModel
[2023-09-10T11:40:19.630+0000] {taskinstance.py:1400} INFO - Marking task as UP_FOR_RETRY. dag_id=file_sensor_dag, task_id=trigger_main_dag, execution_date=20230910T114016, start_date=20230910T114019, end_date=20230910T114019
[2023-09-10T11:40:19.638+0000] {standard_task_runner.py:104} ERROR - Failed to execute job 56 for task trigger_main_dag (Dag id ingest_xl_data_dag not found in DagModel; 924)
[2023-09-10T11:40:19.670+0000] {local_task_job_runner.py:228} INFO - Task exited with return code 1
[2023-09-10T11:40:19.685+0000] {taskinstance.py:2784} INFO - 0 downstream tasks scheduled from follow-on schedule check
