[2023-09-10T09:31:37.757+0000] {taskinstance.py:1159} INFO - Dependencies all met for dep_context=non-requeueable deps ti=<TaskInstance: ingest_xl_to_postgres.sense_file manual__2023-09-10T09:31:36.775244+00:00 [queued]>
[2023-09-10T09:31:37.767+0000] {taskinstance.py:1159} INFO - Dependencies all met for dep_context=requeueable deps ti=<TaskInstance: ingest_xl_to_postgres.sense_file manual__2023-09-10T09:31:36.775244+00:00 [queued]>
[2023-09-10T09:31:37.768+0000] {taskinstance.py:1361} INFO - Starting attempt 1 of 2
[2023-09-10T09:31:37.779+0000] {taskinstance.py:1382} INFO - Executing <Task(FileSensor): sense_file> on 2023-09-10 09:31:36.775244+00:00
[2023-09-10T09:31:37.784+0000] {standard_task_runner.py:57} INFO - Started process 304 to run task
[2023-09-10T09:31:37.788+0000] {standard_task_runner.py:84} INFO - Running: ['***', 'tasks', 'run', 'ingest_xl_to_postgres', 'sense_file', 'manual__2023-09-10T09:31:36.775244+00:00', '--job-id', '34', '--raw', '--subdir', 'DAGS_FOLDER/ingest_xl_data_dag.py', '--cfg-path', '/tmp/tmpffsgz_re']
[2023-09-10T09:31:37.791+0000] {standard_task_runner.py:85} INFO - Job 34: Subtask sense_file
[2023-09-10T09:31:37.836+0000] {task_command.py:415} INFO - Running <TaskInstance: ingest_xl_to_postgres.sense_file manual__2023-09-10T09:31:36.775244+00:00 [running]> on host 207c7509dcbb
[2023-09-10T09:31:38.072+0000] {taskinstance.py:1660} INFO - Exporting env vars: AIRFLOW_CTX_DAG_OWNER='you' AIRFLOW_CTX_DAG_ID='ingest_xl_to_postgres' AIRFLOW_CTX_TASK_ID='sense_file' AIRFLOW_CTX_EXECUTION_DATE='2023-09-10T09:31:36.775244+00:00' AIRFLOW_CTX_TRY_NUMBER='1' AIRFLOW_CTX_DAG_RUN_ID='manual__2023-09-10T09:31:36.775244+00:00'
[2023-09-10T09:31:38.093+0000] {taskinstance.py:1943} ERROR - Task failed with exception
Traceback (most recent call last):
  File "/home/airflow/.local/lib/python3.8/site-packages/airflow/sensors/base.py", line 251, in execute
    raise e
  File "/home/airflow/.local/lib/python3.8/site-packages/airflow/sensors/base.py", line 238, in execute
    poke_return = self.poke(context)
  File "/home/airflow/.local/lib/python3.8/site-packages/airflow/sensors/filesystem.py", line 61, in poke
    hook = FSHook(self.fs_conn_id)
  File "/home/airflow/.local/lib/python3.8/site-packages/airflow/hooks/filesystem.py", line 38, in __init__
    conn = self.get_connection(conn_id)
  File "/home/airflow/.local/lib/python3.8/site-packages/airflow/hooks/base.py", line 72, in get_connection
    conn = Connection.get_connection_from_secrets(conn_id)
  File "/home/airflow/.local/lib/python3.8/site-packages/airflow/models/connection.py", line 477, in get_connection_from_secrets
    raise AirflowNotFoundException(f"The conn_id `{conn_id}` isn't defined")
airflow.exceptions.AirflowNotFoundException: The conn_id `fs_default` isn't defined
[2023-09-10T09:31:38.098+0000] {taskinstance.py:1400} INFO - Marking task as UP_FOR_RETRY. dag_id=ingest_xl_to_postgres, task_id=sense_file, execution_date=20230910T093136, start_date=20230910T093137, end_date=20230910T093138
[2023-09-10T09:31:38.109+0000] {standard_task_runner.py:104} ERROR - Failed to execute job 34 for task sense_file (The conn_id `fs_default` isn't defined; 304)
[2023-09-10T09:31:38.162+0000] {local_task_job_runner.py:228} INFO - Task exited with return code 1
[2023-09-10T09:31:38.184+0000] {taskinstance.py:2784} INFO - 0 downstream tasks scheduled from follow-on schedule check
