[2023-09-10T11:53:54.002+0000] {taskinstance.py:1159} INFO - Dependencies all met for dep_context=non-requeueable deps ti=<TaskInstance: ingest_xl_to_postgres.archive_file manual__2023-09-10T11:44:16.915964+00:00 [queued]>
[2023-09-10T11:53:54.010+0000] {taskinstance.py:1159} INFO - Dependencies all met for dep_context=requeueable deps ti=<TaskInstance: ingest_xl_to_postgres.archive_file manual__2023-09-10T11:44:16.915964+00:00 [queued]>
[2023-09-10T11:53:54.011+0000] {taskinstance.py:1361} INFO - Starting attempt 4 of 4
[2023-09-10T11:53:54.020+0000] {taskinstance.py:1382} INFO - Executing <Task(PythonOperator): archive_file> on 2023-09-10 11:44:16.915964+00:00
[2023-09-10T11:53:54.026+0000] {standard_task_runner.py:57} INFO - Started process 1148 to run task
[2023-09-10T11:53:54.030+0000] {standard_task_runner.py:84} INFO - Running: ['***', 'tasks', 'run', 'ingest_xl_to_postgres', 'archive_file', 'manual__2023-09-10T11:44:16.915964+00:00', '--job-id', '62', '--raw', '--subdir', 'DAGS_FOLDER/ingest_xl_data_dag.py', '--cfg-path', '/tmp/tmpyt63gwia']
[2023-09-10T11:53:54.033+0000] {standard_task_runner.py:85} INFO - Job 62: Subtask archive_file
[2023-09-10T11:53:54.087+0000] {task_command.py:415} INFO - Running <TaskInstance: ingest_xl_to_postgres.archive_file manual__2023-09-10T11:44:16.915964+00:00 [running]> on host 207c7509dcbb
[2023-09-10T11:53:54.327+0000] {taskinstance.py:1660} INFO - Exporting env vars: AIRFLOW_CTX_DAG_OWNER='you' AIRFLOW_CTX_DAG_ID='ingest_xl_to_postgres' AIRFLOW_CTX_TASK_ID='archive_file' AIRFLOW_CTX_EXECUTION_DATE='2023-09-10T11:44:16.915964+00:00' AIRFLOW_CTX_TRY_NUMBER='4' AIRFLOW_CTX_DAG_RUN_ID='manual__2023-09-10T11:44:16.915964+00:00'
[2023-09-10T11:53:54.330+0000] {taskinstance.py:1943} ERROR - Task failed with exception
Traceback (most recent call last):
  File "/home/airflow/.local/lib/python3.8/site-packages/airflow/operators/python.py", line 192, in execute
    return_value = self.execute_callable()
  File "/home/airflow/.local/lib/python3.8/site-packages/airflow/operators/python.py", line 209, in execute_callable
    return self.python_callable(*self.op_args, **self.op_kwargs)
  File "/opt/airflow/dags/ingest_xl_data_dag.py", line 10, in archive_file
    raise FileNotFoundError(f"File {file_path} does not exist!")
FileNotFoundError: File /opt/***/plugins/WordbankEconomicData_Trimmed_v2.xlsx does not exist!
[2023-09-10T11:53:54.340+0000] {taskinstance.py:1400} INFO - Marking task as FAILED. dag_id=ingest_xl_to_postgres, task_id=archive_file, execution_date=20230910T114416, start_date=20230910T115354, end_date=20230910T115354
[2023-09-10T11:53:54.351+0000] {standard_task_runner.py:104} ERROR - Failed to execute job 62 for task archive_file (File /opt/***/plugins/WordbankEconomicData_Trimmed_v2.xlsx does not exist!; 1148)
[2023-09-10T11:53:54.404+0000] {local_task_job_runner.py:228} INFO - Task exited with return code 1
[2023-09-10T11:53:54.423+0000] {taskinstance.py:2784} INFO - 0 downstream tasks scheduled from follow-on schedule check
