[2023-09-10T09:31:35.702+0000] {taskinstance.py:1159} INFO - Dependencies all met for dep_context=non-requeueable deps ti=<TaskInstance: ingest_xl_to_postgres.sense_file scheduled__2023-09-09T00:00:00+00:00 [queued]>
[2023-09-10T09:31:35.711+0000] {taskinstance.py:1159} INFO - Dependencies all met for dep_context=requeueable deps ti=<TaskInstance: ingest_xl_to_postgres.sense_file scheduled__2023-09-09T00:00:00+00:00 [queued]>
[2023-09-10T09:31:35.711+0000] {taskinstance.py:1361} INFO - Starting attempt 1 of 2
[2023-09-10T09:31:35.723+0000] {taskinstance.py:1382} INFO - Executing <Task(FileSensor): sense_file> on 2023-09-09 00:00:00+00:00
[2023-09-10T09:31:35.728+0000] {standard_task_runner.py:57} INFO - Started process 301 to run task
[2023-09-10T09:31:35.732+0000] {standard_task_runner.py:84} INFO - Running: ['***', 'tasks', 'run', 'ingest_xl_to_postgres', 'sense_file', 'scheduled__2023-09-09T00:00:00+00:00', '--job-id', '33', '--raw', '--subdir', 'DAGS_FOLDER/ingest_xl_data_dag.py', '--cfg-path', '/tmp/tmpg5lvm2xh']
[2023-09-10T09:31:35.736+0000] {standard_task_runner.py:85} INFO - Job 33: Subtask sense_file
[2023-09-10T09:31:35.784+0000] {task_command.py:415} INFO - Running <TaskInstance: ingest_xl_to_postgres.sense_file scheduled__2023-09-09T00:00:00+00:00 [running]> on host 207c7509dcbb
[2023-09-10T09:31:36.021+0000] {taskinstance.py:1660} INFO - Exporting env vars: AIRFLOW_CTX_DAG_OWNER='you' AIRFLOW_CTX_DAG_ID='ingest_xl_to_postgres' AIRFLOW_CTX_TASK_ID='sense_file' AIRFLOW_CTX_EXECUTION_DATE='2023-09-09T00:00:00+00:00' AIRFLOW_CTX_TRY_NUMBER='1' AIRFLOW_CTX_DAG_RUN_ID='scheduled__2023-09-09T00:00:00+00:00'
[2023-09-10T09:31:36.044+0000] {taskinstance.py:1943} ERROR - Task failed with exception
Traceback (most recent call last):
  File "/home/airflow/.local/lib/python3.8/site-packages/airflow/sensors/base.py", line 251, in execute
    raise e
  File "/home/airflow/.local/lib/python3.8/site-packages/airflow/sensors/base.py", line 238, in execute
    poke_return = self.poke(context)
  File "/home/airflow/.local/lib/python3.8/site-packages/airflow/sensors/filesystem.py", line 61, in poke
    hook = FSHook(self.fs_conn_id)
  File "/home/airflow/.local/lib/python3.8/site-packages/airflow/hooks/filesystem.py", line 38, in __init__
    conn = self.get_connection(conn_id)
  File "/home/airflow/.local/lib/python3.8/site-packages/airflow/hooks/base.py", line 72, in get_connection
    conn = Connection.get_connection_from_secrets(conn_id)
  File "/home/airflow/.local/lib/python3.8/site-packages/airflow/models/connection.py", line 477, in get_connection_from_secrets
    raise AirflowNotFoundException(f"The conn_id `{conn_id}` isn't defined")
airflow.exceptions.AirflowNotFoundException: The conn_id `fs_default` isn't defined
[2023-09-10T09:31:36.051+0000] {taskinstance.py:1400} INFO - Marking task as UP_FOR_RETRY. dag_id=ingest_xl_to_postgres, task_id=sense_file, execution_date=20230909T000000, start_date=20230910T093135, end_date=20230910T093136
[2023-09-10T09:31:36.064+0000] {standard_task_runner.py:104} ERROR - Failed to execute job 33 for task sense_file (The conn_id `fs_default` isn't defined; 301)
[2023-09-10T09:31:36.105+0000] {local_task_job_runner.py:228} INFO - Task exited with return code 1
[2023-09-10T09:31:36.132+0000] {taskinstance.py:2784} INFO - 0 downstream tasks scheduled from follow-on schedule check
[2023-09-10T10:59:33.009+0000] {taskinstance.py:1159} INFO - Dependencies all met for dep_context=non-requeueable deps ti=<TaskInstance: ingest_xl_to_postgres.sense_file scheduled__2023-09-09T00:00:00+00:00 [queued]>
[2023-09-10T10:59:33.021+0000] {taskinstance.py:1159} INFO - Dependencies all met for dep_context=requeueable deps ti=<TaskInstance: ingest_xl_to_postgres.sense_file scheduled__2023-09-09T00:00:00+00:00 [queued]>
[2023-09-10T10:59:33.022+0000] {taskinstance.py:1361} INFO - Starting attempt 1 of 2
[2023-09-10T10:59:33.035+0000] {taskinstance.py:1382} INFO - Executing <Task(FileSensor): sense_file> on 2023-09-09 00:00:00+00:00
[2023-09-10T10:59:33.042+0000] {standard_task_runner.py:57} INFO - Started process 285 to run task
[2023-09-10T10:59:33.046+0000] {standard_task_runner.py:84} INFO - Running: ['***', 'tasks', 'run', 'ingest_xl_to_postgres', 'sense_file', 'scheduled__2023-09-09T00:00:00+00:00', '--job-id', '44', '--raw', '--subdir', 'DAGS_FOLDER/ingest_xl_data_dag.py', '--cfg-path', '/tmp/tmpobe988h5']
[2023-09-10T10:59:33.051+0000] {standard_task_runner.py:85} INFO - Job 44: Subtask sense_file
[2023-09-10T10:59:33.101+0000] {task_command.py:415} INFO - Running <TaskInstance: ingest_xl_to_postgres.sense_file scheduled__2023-09-09T00:00:00+00:00 [running]> on host 207c7509dcbb
[2023-09-10T10:59:33.345+0000] {taskinstance.py:1660} INFO - Exporting env vars: AIRFLOW_CTX_DAG_OWNER='you' AIRFLOW_CTX_DAG_ID='ingest_xl_to_postgres' AIRFLOW_CTX_TASK_ID='sense_file' AIRFLOW_CTX_EXECUTION_DATE='2023-09-09T00:00:00+00:00' AIRFLOW_CTX_TRY_NUMBER='1' AIRFLOW_CTX_DAG_RUN_ID='scheduled__2023-09-09T00:00:00+00:00'
[2023-09-10T10:59:33.357+0000] {base.py:73} INFO - Using connection ID 'fs_default' for task execution.
[2023-09-10T10:59:33.358+0000] {filesystem.py:64} INFO - Poking for file /opt/***/plugins/WordbankEconomicData_Trimmed_v2.xlsx
[2023-09-10T11:00:03.368+0000] {base.py:73} INFO - Using connection ID 'fs_default' for task execution.
[2023-09-10T11:00:03.370+0000] {filesystem.py:64} INFO - Poking for file /opt/***/plugins/WordbankEconomicData_Trimmed_v2.xlsx
[2023-09-10T11:00:33.361+0000] {base.py:73} INFO - Using connection ID 'fs_default' for task execution.
[2023-09-10T11:00:33.362+0000] {filesystem.py:64} INFO - Poking for file /opt/***/plugins/WordbankEconomicData_Trimmed_v2.xlsx
[2023-09-10T11:00:38.514+0000] {local_task_job_runner.py:294} WARNING - State of this instance has been externally set to None. Terminating instance.
[2023-09-10T11:00:38.517+0000] {process_utils.py:131} INFO - Sending 15 to group 285. PIDs of all processes in the group: [285]
[2023-09-10T11:00:38.518+0000] {process_utils.py:86} INFO - Sending the signal 15 to group 285
[2023-09-10T11:00:38.519+0000] {taskinstance.py:1632} ERROR - Received SIGTERM. Terminating subprocesses.
[2023-09-10T11:00:38.528+0000] {taskinstance.py:1943} ERROR - Task failed with exception
Traceback (most recent call last):
  File "/home/airflow/.local/lib/python3.8/site-packages/airflow/sensors/base.py", line 279, in execute
    time.sleep(self._get_next_poke_interval(started_at, run_duration, try_number))
  File "/home/airflow/.local/lib/python3.8/site-packages/airflow/models/taskinstance.py", line 1634, in signal_handler
    raise AirflowException("Task received SIGTERM signal")
airflow.exceptions.AirflowException: Task received SIGTERM signal
[2023-09-10T11:00:38.532+0000] {taskinstance.py:1400} INFO - Marking task as FAILED. dag_id=ingest_xl_to_postgres, task_id=sense_file, execution_date=20230909T000000, start_date=20230910T105933, end_date=20230910T110038
[2023-09-10T11:00:38.544+0000] {standard_task_runner.py:104} ERROR - Failed to execute job 44 for task sense_file ((psycopg2.errors.ForeignKeyViolation) insert or update on table "task_fail" violates foreign key constraint "task_fail_ti_fkey"
DETAIL:  Key (dag_id, task_id, run_id, map_index)=(ingest_xl_to_postgres, sense_file, scheduled__2023-09-09T00:00:00+00:00, -1) is not present in table "task_instance".

[SQL: INSERT INTO task_fail (task_id, dag_id, run_id, map_index, start_date, end_date, duration) VALUES (%(task_id)s, %(dag_id)s, %(run_id)s, %(map_index)s, %(start_date)s, %(end_date)s, %(duration)s) RETURNING task_fail.id]
[parameters: {'task_id': 'sense_file', 'dag_id': 'ingest_xl_to_postgres', 'run_id': 'scheduled__2023-09-09T00:00:00+00:00', 'map_index': -1, 'start_date': datetime.datetime(2023, 9, 10, 10, 59, 33, 11725, tzinfo=Timezone('UTC')), 'end_date': datetime.datetime(2023, 9, 10, 11, 0, 38, 531883, tzinfo=Timezone('UTC')), 'duration': 65}]
(Background on this error at: https://sqlalche.me/e/14/gkpj); 285)
[2023-09-10T11:00:38.571+0000] {process_utils.py:79} INFO - Process psutil.Process(pid=285, status='terminated', exitcode=1, started='10:59:32') (285) terminated with exit code 1
